# 프로그램에서 자주 발생하는 예외들
- FileNotFoundException   
존재하지 않는 파일을 열려고 시도할 때(FileReader)   
   
- ArithmeticException   
산술 오류   
   
- ArrayIndexOutOfBoundsException   
배열에서 index에러   
   
# 예외 처리하기 (try ~ catch문)
기본 구조   
```Java
try {
    <수행할 문장 1>;
    <수행할 문장 2>;
    ...
} catch(예외1) {
    <수행할 문장 A>;
    ...
} catch(예외2) {
    <수행할 문장 a>;
    ...
}
```
try 문 안의 수행할 문장 중에서 예외가 발생하지 않는다면 catch 문에 속한 문장들은 수행되지 않음   
-> try 문장 수행 도중에 예외가 발생하면 예외에 해당하는 catch 문이 수행   

```Java
// ArithmeticException 오류 예시
public class Sample {
    public static void main(String[] args) {
        int c;
        try {
            c = 4 / 0;
        } catch(ArithmeticException e) {
            // ArithmeticException 클래스의 e 객체(예외 객체)
            // 예외가 발생하여 이 문장이 수행된다.
            c = -1;
        }
    }
}
```
ArithmeticException 에러가 발생하면 c에 -1을 대입하도록 예외를 처리한 것   
ArithmeticException e에서 e는 ArithmeticException 클래스의 객체, 즉 예외 객체에 해당   
이 예외 객체를 통해 해당 예외 클래스의 변수나 메서드를 호출할 수 있음   
-> 자바의 예외 처리 메커니즘은 클래스 기반으로 오류(예외)들도 기본적으로 클래스를 가짐(java.lang.Throwable)   

# Vue와의 비교
- 목적   
Java의 try-catch는 동기 코드에서 발생하는 예외를 처리   
Vue의 then-catch는 비동기 작업(promise)에서 발생하는 예외를 처리   
   
- 문법   
Java의 try 블록 내에서 예외 발생 시 catch 블록으로 제어가 이동   
Vue의 성공하면 then 블록 처리, 실패 시 catch 블록 처리    

# Python과의 비교
Python의 try-except문과 매우 유사   
```Python
# python
try:
    file = open('test.txt', 'r')
    # 파일을 읽는 코드
except FileNotFoundError as e:
    print("File not found:", e)
```
```Java
// Java
try {
    File file = new File("test.txt");
    FileReader fr = new FileReader(file);
    // 파일을 읽는 코드
} catch (FileNotFoundException e) {
    System.out.println("File not found: " + e.getMessage());
}
```
위의 두 언어 모두 동기 코드에서 발생할 수 있는 예외를 처리하기 위해 사용   
-> 비동기 경우, Python은 async, await 사용   

# finally
프로그램 수행 도중 예외가 발생하면 프로그램이 중지되거나 예외 처리에 의해 catch 구문이 실행됨   
-> 어떤 예외가 발생하더라도 반드시 실행되어야 하는 부분이 있다면?   

```Java
public class Sample {
    public void shouldBeRun() {
        System.out.println("ok thanks.");
    }

    public static void main(String[] args) {
        Sample sample = new Sample();
        int c;
        try {
            c = 4 / 0;
            // 밑에 sample.shouldBeRun은 실행되지 않음
            // 4/0에 의해 ArithmeticException 에러가 발생 catch 구문으로 넘어감
            sample.shouldBeRun();  
        } catch (ArithmeticException e) {
            c = -1;
        }
    }
}
```

```Java
public class Sample {
    public void shouldBeRun() {
        System.out.println("ok thanks");
    }

    public static void main(String[] args) {
        Sample sample = new Sample();
        int c;
        try {
            c = 4 / 0;
        } catch (ArithmeticException e) {
            c = -1;
        } finally {
            sample.shouldBeRun();  // 예외에 상관없이 무조건 수행된다.
        }
    }
}
```
에러 발생 후 catch 구문 실행 c = -1   
finally 구문 실행   

# 예외 활용하기 - RuntimeException
RuntimeException : 실행 시 발생하는 예외   
-> 발생할 수도 있고, 발생하지 않을 수도 있는 경우 사용(Unchecked Exception)   
-> 컴파일러가 예외 처리를 강제하지 않음   

```Java
// 오류 클래스 상속
class FoolException extends RuntimeException {
}

public class Sample {
    public void sayNick(String nick) {
        if("바보".equals(nick)) {
          // return; 대신 예외 처리 
            throw new FoolException();
        }
        System.out.println("당신의 별명은 "+nick+" 입니다.");
    }

    public static void main(String[] args) {
        Sample sample = new Sample();
        sample.sayNick("바보");
        sample.sayNick("야호");
    }
}
```
위 프로그램을 실행하면 '바보'라는 입력값으로 sayNick 메서드 실행 시 다음과 같은 예외가 발생
```Java
Exception in thread "main" FoolException
    at Sample.sayNick(Sample.java:7)
    at Sample.main(Sample.java:14)
```

# 예외 활용하기 - Exception
Exception : 컴파일 시 발생하는 예외   
-> 예측이 가능한 경우 사용(Checked Exception)   
RuntimeException을 상속하던 것을 Exception을 상속하도록 변경   
-> Sample 클래스에서 컴파일 오류가 발생   
-> FoolException이 예측 가능한 Checked Exception으로 변경되어 예외 처리를 컴파일러가 강제하기 때문   

```Java
// Exception 상속으로 변경
class FoolException extends Exception {
}

public class Sample {
    public void sayNick(String nick) {
      // try, catch 구문 추가
      // 컴파일러가 강제해서 안 쓰면 컴파일 오류
        try {
            if("바보".equals(nick)) {
              // throw로 예외(FoolException) 발생
                throw new FoolException();
            }
            System.out.println("당신의 별명은 "+nick+" 입니다.");
        }catch(FoolException e) {
            System.err.println("FoolException이 발생했습니다.");
        }
    }

    public static void main(String[] args) {
        Sample sample = new Sample();
        sample.sayNick("바보");
        sample.sayNick("야호");
    }
}
```

# 예외 던지기 (throws)
위 예제에서는 sayNick 메서드에서 FoolException을 발생시키고(throw) 예외 처리도 sayNick 메서드에서 했음   
하지만 이렇게 하지 않고 sayNick을 호출한 곳에서 FoolException을 처리하도록 예외를 위로 던질 수 있음   
-> throws 구문 사용 (예외를 뒤로 미루기)

```Java
class FoolException extends Exception {
}

public class Sample {
  // throws 구문 이용
    public void sayNick(String nick) throws FoolException {
        if("바보".equals(nick)) {
            throw new FoolException();
        }
        System.out.println("당신의 별명은 "+nick+" 입니다.");
    }

    public static void main(String[] args) {
        Sample sample = new Sample();
        // main 메서드에서 try ~ catch 문으로 sayNick 메서드에 대한 FoolException 예외를 처리
        try {
            sample.sayNick("바보");
            sample.sayNick("야호");
        } catch (FoolException e) {
            System.err.println("FoolException이 발생했습니다.");
        }
    }
}
```
throws 구문 때문에 FoolException의 예외를 처리해야 하는 대상이 sayNick 메서드에서 main 메서드(sayNick 메서드를 호출하는 메서드)로 변경됨   
-> 따라서 예외 처리 구문이 main 메서드로 옮겨짐   
   
sayNick 메서드에서 예외 처리했을 때는 바보와 야호 두 문장이 모두 수행됐었음   
   
main 메서드에서 예외 처리를 한 경우는 첫 번째 문장에서 예외가 발생하여 catch문으로 빠지기 때문에 두 번째 문장이 수행되지 않음   
   
-> 예외를 처리하는 위치는 프로그램의 수행여부를 결정함   

# 트랜잭션(transaction)
트랜잭션은 하나의 작업 단위를 뜻함   
예를 들어 쇼핑몰의 '상품발송'이라는 트랜잭션을 가정하면,   
포장, 영수증 발행, 발송 등이 포함됨   
트랜잭션 -> 상품 발송 트랜잭션(포장, 영수증 발행, 발송) -> 트랜잭션   
상품 발송의 3가지 작업 중 하나라도 실패하면 3가지 모두 취소하고 '상품발송' 전의 상태로 되돌리려면?   
```Java
// 슈도코드
상품발송() {
    try {
        포장();
        영수증발행();
        발송();
    }catch(예외) {
        모두취소();  // 하나라도 실패하면 모두 취소한다.
    }
}

포장() throws 예외 {
   ...
}

영수증발행() throws 예외 {
   ...
}

발송() throws 예외 {
   ...
}
```
포장, 영수증발행, 발송 메서드에서 각각 예외를 던지고, 상품발송 메서드에서 던져진 예외를 처리한 뒤 모두 취소하는 것이 완벽한 트랜잭션 처리 방법!   

```Java
상품발송() {
    포장();
    영수증발행();
    발송();
}

포장(){
    try {
       ...
    }catch(예외) {
       포장취소();
    }
}

영수증발행() {
    try {
       ...
    }catch(예외) {
       영수증발행취소();
    }
}

발송() {
    try {
       ...
    }catch(예외) {
       발송취소();
    }
}

```
이렇게 각각의 메서드에서 예외 처리를 하면 난리남   
자바의 예외 처리는 다소 어려운 부분